[I 2024-04-06 09:07:32.479 ServerApp] Package jupyterlab took 0.0000s to import
[I 2024-04-06 09:07:32.598 ServerApp] Package jupyter_lsp took 0.1181s to import
[W 2024-04-06 09:07:32.598 ServerApp] A `_jupyter_server_extension_points` function was not found in jupyter_lsp. Instead, a `_jupyter_server_extension_paths` function was found and will be used for now. This function name will be deprecated in future releases of Jupyter Server.
[I 2024-04-06 09:07:32.664 ServerApp] Package jupyter_server_terminals took 0.0653s to import
[I 2024-04-06 09:07:33.378 ServerApp] Package jupytext took 0.7133s to import
[I 2024-04-06 09:07:33.379 ServerApp] Package notebook_shim took 0.0000s to import
[W 2024-04-06 09:07:33.379 ServerApp] A `_jupyter_server_extension_points` function was not found in notebook_shim. Instead, a `_jupyter_server_extension_paths` function was found and will be used for now. This function name will be deprecated in future releases of Jupyter Server.
[I 2024-04-06 09:07:33.409 ServerApp] jupyter_lsp | extension was successfully linked.
[I 2024-04-06 09:07:33.422 ServerApp] jupyter_server_terminals | extension was successfully linked.
[I 2024-04-06 09:07:33.438 ServerApp] jupyterlab | extension was successfully linked.
[I 2024-04-06 09:07:33.439 ServerApp] jupytext | extension was successfully linked.
[I 2024-04-06 09:07:34.774 ServerApp] Package jupyter_nbextensions_configurator took 1.0134s to import
[W 2024-04-06 09:07:34.774 ServerApp] A `_jupyter_server_extension_points` function was not found in jupyter_nbextensions_configurator. Instead, a `_jupyter_server_extension_paths` function was found and will be used for now. This function name will be deprecated in future releases of Jupyter Server.
[I 2024-04-06 09:07:34.774 ServerApp] jupyter_nbextensions_configurator | extension was found and enabled by notebook_shim. Consider moving the extension to Jupyter Server's extension paths.
[I 2024-04-06 09:07:34.774 ServerApp] jupyter_nbextensions_configurator | extension was successfully linked.
[I 2024-04-06 09:07:34.774 ServerApp] notebook_shim | extension was successfully linked.
[I 2024-04-06 09:07:34.933 ServerApp] notebook_shim | extension was successfully loaded.
[I 2024-04-06 09:07:34.941 ServerApp] jupyter_lsp | extension was successfully loaded.
[I 2024-04-06 09:07:34.942 ServerApp] [jupyter_nbextensions_configurator] enabled 0.6.3
[I 2024-04-06 09:07:34.942 ServerApp] jupyter_nbextensions_configurator | extension was successfully loaded.
[I 2024-04-06 09:07:34.944 ServerApp] jupyter_server_terminals | extension was successfully loaded.
[I 2024-04-06 09:07:34.949 LabApp] JupyterLab extension loaded from /home/hass/base/lib/python3.11/site-packages/jupyterlab
[I 2024-04-06 09:07:34.949 LabApp] JupyterLab application directory is /home/hass/base/share/jupyter/lab
[I 2024-04-06 09:07:34.950 LabApp] Extension Manager is 'pypi'.
[I 2024-04-06 09:07:34.958 ServerApp] jupyterlab | extension was successfully loaded.
[W 2024-04-06 09:07:34.958 ServerApp] [Jupytext Server Extension] Async contents managers like AsyncLargeFileManager are not supported at the moment (https://github.com/mwouts/jupytext/issues/1020). We will derive a contents manager from LargeFileManager instead.
[I 2024-04-06 09:07:34.958 ServerApp] [Jupytext Server Extension] Deriving a JupytextContentsManager from LargeFileManager
[I 2024-04-06 09:07:34.961 ServerApp] jupytext | extension was successfully loaded.
[I 2024-04-06 09:07:34.963 ServerApp] Serving notebooks from local directory: /home/hass/Documents/webdev/dev2
[I 2024-04-06 09:07:34.963 ServerApp] Jupyter Server 2.10.1 is running at:
[I 2024-04-06 09:07:34.963 ServerApp] http://localhost:8888/lab
[I 2024-04-06 09:07:34.963 ServerApp]     http://127.0.0.1:8888/lab
[I 2024-04-06 09:07:34.963 ServerApp] Use Control-C to stop this server and shut down all kernels (twice to skip confirmation).
[I 2024-04-06 09:07:36.090 ServerApp] Skipped non-installed server(s): bash-language-server, dockerfile-language-server-nodejs, javascript-typescript-langserver, jedi-language-server, julia-language-server, pyright, python-language-server, python-lsp-server, sql-language-server, texlab, typescript-language-server, unified-language-server, vscode-css-languageserver-bin, vscode-html-languageserver-bin, vscode-json-languageserver-bin, yaml-language-server
0.00s - Debugger warning: It seems that frozen modules are being used, which may
0.00s - make the debugger miss breakpoints. Please pass -Xfrozen_modules=off
0.00s - to python to disable frozen modules.
0.00s - Note: Debugging will proceed. Set PYDEVD_DISABLE_FILE_VALIDATION=1 to disable this validation.
[W 2024-04-06 09:07:43.204 ServerApp] 404 GET /api/contents/Untitled1.ipynb?content=0&1712390863192 (bccbc04e7c1d42f299202d7a3f8129a7@127.0.0.1) 0.99ms referer=http://localhost:8888/lab/tree/Untitled1.ipynb
[W 2024-04-06 09:07:43.204 ServerApp] 404 GET /api/contents/Untitled1.ipynb?content=0&1712390863192 (127.0.0.1): file or directory does not exist: 'Untitled1.ipynb'
[W 2024-04-06 09:07:43.207 ServerApp] 404 GET /api/contents/img/icons/Untitled.ipynb?content=0&1712390863192 (bccbc04e7c1d42f299202d7a3f8129a7@127.0.0.1) 0.89ms referer=http://localhost:8888/lab/tree/Untitled1.ipynb
[W 2024-04-06 09:07:43.207 ServerApp] 404 GET /api/contents/img/icons/Untitled.ipynb?content=0&1712390863192 (127.0.0.1): file or directory does not exist: 'img/icons/Untitled.ipynb'
[W 2024-04-06 09:07:43.353 ServerApp] 404 GET /api/contents/Untitled.ipynb?content=0&1712390863191 (bccbc04e7c1d42f299202d7a3f8129a7@127.0.0.1) 0.87ms referer=http://localhost:8888/lab/tree/Untitled1.ipynb
[W 2024-04-06 09:07:43.353 ServerApp] 404 GET /api/contents/Untitled.ipynb?content=0&1712390863191 (127.0.0.1): file or directory does not exist: 'Untitled.ipynb'
[I 2024-04-06 09:07:43.468 LabApp] Build is up to date
[W 2024-04-06 09:07:44.597 ServerApp] 404 GET /api/contents/Untitled1.ipynb?content=0&1712390864593 (bccbc04e7c1d42f299202d7a3f8129a7@127.0.0.1) 0.97ms referer=http://localhost:8888/lab/tree/Untitled1.ipynb
[W 2024-04-06 09:07:44.598 ServerApp] 404 GET /api/contents/Untitled1.ipynb?content=0&1712390864593 (127.0.0.1): file or directory does not exist: 'Untitled1.ipynb'
[W 2024-04-06 12:18:00.467 ServerApp] 404 GET /hub/api (@127.0.0.1) 154.87ms referer=None
[W 2024-04-06 12:18:00.479 ServerApp] 404 GET /hub/api (@127.0.0.1) 1.27ms referer=None
[W 2024-04-06 12:18:00.480 ServerApp] 404 GET /hub/api (@127.0.0.1) 1.11ms referer=None
[W 2024-04-06 12:18:00.481 ServerApp] 404 GET /hub/api (@127.0.0.1) 1.75ms referer=None
[W 2024-04-06 12:18:00.580 ServerApp] 404 GET /tree? (@127.0.0.1) 1.04ms referer=None
[W 2024-04-06 12:18:00.843 ServerApp] 404 GET /tree? (@127.0.0.1) 1.13ms referer=None
[W 2024-04-06 12:18:00.859 ServerApp] 404 GET /tree? (@127.0.0.1) 1.10ms referer=None
[W 2024-04-06 12:18:00.861 ServerApp] 404 GET /tree? (@127.0.0.1) 0.84ms referer=None
[W 2024-04-06 12:18:01.596 ServerApp] wrote error: 'Forbidden'
    Traceback (most recent call last):
      File "/home/hass/base/lib/python3.11/site-packages/tornado/web.py", line 1784, in _execute
        result = method(*self.path_args, **self.path_kwargs)
                 ^^^^^^^^^^^^^^^^^^^^^^^^^^^^^^^^^^^^^^^^^^^
      File "/home/hass/base/lib/python3.11/site-packages/tornado/web.py", line 3278, in wrapper
        url = self.get_login_url()
              ^^^^^^^^^^^^^^^^^^^^
      File "/home/hass/base/lib/python3.11/site-packages/jupyter_server/base/handlers.py", line 761, in get_login_url
        raise web.HTTPError(403)
    tornado.web.HTTPError: HTTP 403: Forbidden
[W 2024-04-06 12:18:01.795 ServerApp] 403 GET /api/kernelspecs?1712402280957 (@127.0.0.1) 199.22ms referer=None
[W 2024-04-06 12:18:01.796 ServerApp] wrote error: 'Forbidden'
    Traceback (most recent call last):
      File "/home/hass/base/lib/python3.11/site-packages/tornado/web.py", line 1784, in _execute
        result = method(*self.path_args, **self.path_kwargs)
                 ^^^^^^^^^^^^^^^^^^^^^^^^^^^^^^^^^^^^^^^^^^^
      File "/home/hass/base/lib/python3.11/site-packages/tornado/web.py", line 3278, in wrapper
        url = self.get_login_url()
              ^^^^^^^^^^^^^^^^^^^^
      File "/home/hass/base/lib/python3.11/site-packages/jupyter_server/base/handlers.py", line 761, in get_login_url
        raise web.HTTPError(403)
    tornado.web.HTTPError: HTTP 403: Forbidden
[W 2024-04-06 12:18:01.796 ServerApp] 403 GET /api/kernels?1712402280967 (@127.0.0.1) 1.45ms referer=None
[W 2024-04-06 12:18:01.797 ServerApp] wrote error: 'Forbidden'
    Traceback (most recent call last):
      File "/home/hass/base/lib/python3.11/site-packages/tornado/web.py", line 1784, in _execute
        result = method(*self.path_args, **self.path_kwargs)
                 ^^^^^^^^^^^^^^^^^^^^^^^^^^^^^^^^^^^^^^^^^^^
      File "/home/hass/base/lib/python3.11/site-packages/tornado/web.py", line 3278, in wrapper
        url = self.get_login_url()
              ^^^^^^^^^^^^^^^^^^^^
      File "/home/hass/base/lib/python3.11/site-packages/jupyter_server/base/handlers.py", line 761, in get_login_url
        raise web.HTTPError(403)
    tornado.web.HTTPError: HTTP 403: Forbidden
[W 2024-04-06 12:18:01.797 ServerApp] 403 GET /api/kernelspecs?1712402280973 (@127.0.0.1) 2.12ms referer=None
[W 2024-04-06 12:18:01.798 ServerApp] wrote error: 'Forbidden'
    Traceback (most recent call last):
      File "/home/hass/base/lib/python3.11/site-packages/tornado/web.py", line 1784, in _execute
        result = method(*self.path_args, **self.path_kwargs)
                 ^^^^^^^^^^^^^^^^^^^^^^^^^^^^^^^^^^^^^^^^^^^
      File "/home/hass/base/lib/python3.11/site-packages/tornado/web.py", line 3278, in wrapper
        url = self.get_login_url()
              ^^^^^^^^^^^^^^^^^^^^
      File "/home/hass/base/lib/python3.11/site-packages/jupyter_server/base/handlers.py", line 761, in get_login_url
        raise web.HTTPError(403)
    tornado.web.HTTPError: HTTP 403: Forbidden
[W 2024-04-06 12:18:01.799 ServerApp] 403 GET /api/kernels?1712402280974 (@127.0.0.1) 1.35ms referer=None
[W 2024-04-06 12:18:01.799 ServerApp] wrote error: 'Forbidden'
    Traceback (most recent call last):
      File "/home/hass/base/lib/python3.11/site-packages/tornado/web.py", line 1784, in _execute
        result = method(*self.path_args, **self.path_kwargs)
                 ^^^^^^^^^^^^^^^^^^^^^^^^^^^^^^^^^^^^^^^^^^^
      File "/home/hass/base/lib/python3.11/site-packages/tornado/web.py", line 3278, in wrapper
        url = self.get_login_url()
              ^^^^^^^^^^^^^^^^^^^^
      File "/home/hass/base/lib/python3.11/site-packages/jupyter_server/base/handlers.py", line 761, in get_login_url
        raise web.HTTPError(403)
    tornado.web.HTTPError: HTTP 403: Forbidden
[W 2024-04-06 12:18:01.800 ServerApp] 403 GET /api/kernels?1712402280975 (@127.0.0.1) 1.96ms referer=None
[W 2024-04-06 12:18:01.801 ServerApp] wrote error: 'Forbidden'
    Traceback (most recent call last):
      File "/home/hass/base/lib/python3.11/site-packages/tornado/web.py", line 1784, in _execute
        result = method(*self.path_args, **self.path_kwargs)
                 ^^^^^^^^^^^^^^^^^^^^^^^^^^^^^^^^^^^^^^^^^^^
      File "/home/hass/base/lib/python3.11/site-packages/tornado/web.py", line 3278, in wrapper
        url = self.get_login_url()
              ^^^^^^^^^^^^^^^^^^^^
      File "/home/hass/base/lib/python3.11/site-packages/jupyter_server/base/handlers.py", line 761, in get_login_url
        raise web.HTTPError(403)
    tornado.web.HTTPError: HTTP 403: Forbidden
[W 2024-04-06 12:18:01.801 ServerApp] 403 GET /api/sessions?1712402280977 (@127.0.0.1) 1.56ms referer=None
[W 2024-04-06 12:18:01.802 ServerApp] wrote error: 'Forbidden'
    Traceback (most recent call last):
      File "/home/hass/base/lib/python3.11/site-packages/tornado/web.py", line 1784, in _execute
        result = method(*self.path_args, **self.path_kwargs)
                 ^^^^^^^^^^^^^^^^^^^^^^^^^^^^^^^^^^^^^^^^^^^
      File "/home/hass/base/lib/python3.11/site-packages/tornado/web.py", line 3278, in wrapper
        url = self.get_login_url()
              ^^^^^^^^^^^^^^^^^^^^
      File "/home/hass/base/lib/python3.11/site-packages/jupyter_server/base/handlers.py", line 761, in get_login_url
        raise web.HTTPError(403)
    tornado.web.HTTPError: HTTP 403: Forbidden
[W 2024-04-06 12:18:01.802 ServerApp] 403 GET /api/kernels?1712402280983 (@127.0.0.1) 2.25ms referer=None
[W 2024-04-06 12:18:01.802 ServerApp] wrote error: 'Forbidden'
    Traceback (most recent call last):
      File "/home/hass/base/lib/python3.11/site-packages/tornado/web.py", line 1784, in _execute
        result = method(*self.path_args, **self.path_kwargs)
                 ^^^^^^^^^^^^^^^^^^^^^^^^^^^^^^^^^^^^^^^^^^^
      File "/home/hass/base/lib/python3.11/site-packages/tornado/web.py", line 3278, in wrapper
        url = self.get_login_url()
              ^^^^^^^^^^^^^^^^^^^^
      File "/home/hass/base/lib/python3.11/site-packages/jupyter_server/base/handlers.py", line 761, in get_login_url
        raise web.HTTPError(403)
    tornado.web.HTTPError: HTTP 403: Forbidden
[W 2024-04-06 12:18:01.803 ServerApp] 403 GET /api/sessions?1712402280985 (@127.0.0.1) 2.88ms referer=None
[W 2024-04-06 12:18:01.814 ServerApp] wrote error: 'Forbidden'
    Traceback (most recent call last):
      File "/home/hass/base/lib/python3.11/site-packages/tornado/web.py", line 1784, in _execute
        result = method(*self.path_args, **self.path_kwargs)
                 ^^^^^^^^^^^^^^^^^^^^^^^^^^^^^^^^^^^^^^^^^^^
      File "/home/hass/base/lib/python3.11/site-packages/tornado/web.py", line 3278, in wrapper
        url = self.get_login_url()
              ^^^^^^^^^^^^^^^^^^^^
      File "/home/hass/base/lib/python3.11/site-packages/jupyter_server/base/handlers.py", line 761, in get_login_url
        raise web.HTTPError(403)
    tornado.web.HTTPError: HTTP 403: Forbidden
[W 2024-04-06 12:18:01.815 ServerApp] 403 GET /api/kernelspecs?1712402281693 (@127.0.0.1) 1.33ms referer=None
[W 2024-04-06 12:18:01.816 ServerApp] wrote error: 'Forbidden'
    Traceback (most recent call last):
      File "/home/hass/base/lib/python3.11/site-packages/tornado/web.py", line 1784, in _execute
        result = method(*self.path_args, **self.path_kwargs)
                 ^^^^^^^^^^^^^^^^^^^^^^^^^^^^^^^^^^^^^^^^^^^
      File "/home/hass/base/lib/python3.11/site-packages/tornado/web.py", line 3278, in wrapper
        url = self.get_login_url()
              ^^^^^^^^^^^^^^^^^^^^
      File "/home/hass/base/lib/python3.11/site-packages/jupyter_server/base/handlers.py", line 761, in get_login_url
        raise web.HTTPError(403)
    tornado.web.HTTPError: HTTP 403: Forbidden
[W 2024-04-06 12:18:01.816 ServerApp] 403 GET /api/kernels?1712402281695 (@127.0.0.1) 1.00ms referer=None
[W 2024-04-06 12:18:01.905 ServerApp] wrote error: 'Forbidden'
    Traceback (most recent call last):
      File "/home/hass/base/lib/python3.11/site-packages/tornado/web.py", line 1784, in _execute
        result = method(*self.path_args, **self.path_kwargs)
                 ^^^^^^^^^^^^^^^^^^^^^^^^^^^^^^^^^^^^^^^^^^^
      File "/home/hass/base/lib/python3.11/site-packages/tornado/web.py", line 3278, in wrapper
        url = self.get_login_url()
              ^^^^^^^^^^^^^^^^^^^^
      File "/home/hass/base/lib/python3.11/site-packages/jupyter_server/base/handlers.py", line 761, in get_login_url
        raise web.HTTPError(403)
    tornado.web.HTTPError: HTTP 403: Forbidden
[W 2024-04-06 12:18:01.906 ServerApp] 403 GET /api/kernels?1712402281814 (@127.0.0.1) 1.15ms referer=None
[W 2024-04-06 12:18:01.907 ServerApp] wrote error: 'Forbidden'
    Traceback (most recent call last):
      File "/home/hass/base/lib/python3.11/site-packages/tornado/web.py", line 1784, in _execute
        result = method(*self.path_args, **self.path_kwargs)
                 ^^^^^^^^^^^^^^^^^^^^^^^^^^^^^^^^^^^^^^^^^^^
      File "/home/hass/base/lib/python3.11/site-packages/tornado/web.py", line 3278, in wrapper
        url = self.get_login_url()
              ^^^^^^^^^^^^^^^^^^^^
      File "/home/hass/base/lib/python3.11/site-packages/jupyter_server/base/handlers.py", line 761, in get_login_url
        raise web.HTTPError(403)
    tornado.web.HTTPError: HTTP 403: Forbidden
[W 2024-04-06 12:18:01.907 ServerApp] 403 GET /api/sessions?1712402281818 (@127.0.0.1) 0.87ms referer=None
[W 2024-04-06 12:18:01.912 ServerApp] wrote error: 'Forbidden'
    Traceback (most recent call last):
      File "/home/hass/base/lib/python3.11/site-packages/tornado/web.py", line 1784, in _execute
        result = method(*self.path_args, **self.path_kwargs)
                 ^^^^^^^^^^^^^^^^^^^^^^^^^^^^^^^^^^^^^^^^^^^
      File "/home/hass/base/lib/python3.11/site-packages/tornado/web.py", line 3278, in wrapper
        url = self.get_login_url()
              ^^^^^^^^^^^^^^^^^^^^
      File "/home/hass/base/lib/python3.11/site-packages/jupyter_server/base/handlers.py", line 761, in get_login_url
        raise web.HTTPError(403)
    tornado.web.HTTPError: HTTP 403: Forbidden
[W 2024-04-06 12:18:01.913 ServerApp] 403 GET /api/kernelspecs?1712402281905 (@127.0.0.1) 1.27ms referer=None
[I 2024-04-06 12:18:05.950 ServerApp] User 53fbc83d543b41058794970421bbab0e logged in.
[I 2024-04-06 12:18:05.950 ServerApp] 302 POST /login? (53fbc83d543b41058794970421bbab0e@127.0.0.1) 321.94ms
